<mujoco model="acrobot">
    <compiler angle="degree" coordinate="local"/>
    <option timestep="0.01" gravity="0 0 -9.81"/>

    <default>
        <joint limited="true" damping="0.01"/>
        <geom type="capsule" size="0.02" rgba="0.2 0.4 0.6 1" mass="1"/>
    </default>

    <worldbody>
    <light name="light" pos="0 0 6"/>
    <geom name="floor" size="3 3 .2" type="plane"/>
    <site name="target" type="sphere" pos="0 0 4" size="0.2" group="3"/>
    <camera name="fixed" pos="0 -6 2" zaxis="0 -1 0"/>
    <camera name="lookat" mode="targetbodycom" target="upper_arm" pos="0 -2 3"/>
    <body name="upper_arm" pos="0 0 2">
      <geom name="upper_arm" fromto="0 0 0 0 0 1" size="0.049" />
      <joint name="shoulder" type="hinge" axis="0 1 0" range="-180 180"/>
      <site name="wind_site" pos="0 0 0.5" size="0.01" type="sphere"/>
      <body name="lower_arm" pos="0 0 1">
        <joint name="elbow" type="hinge" axis="0 1 0" range="-180 180"/>
        <geom name="lower_arm" fromto="0 0 0 0 0 1" size="0.049" />
        <site name="tip" pos="0 0 1" size="0.01"/>
      </body>
    </body>
  </worldbody>

    <actuator>
        <!-- Only second joint is actuated -->
        <motor joint="elbow" ctrlrange="-1.0 1.0" />
    </actuator>
</mujoco>
